Workbook

Sheet Leeme
A1: Zaqora (concepto Ghost Engine) - Modelo económico, semana 7
A2: Proyecto de Ingeniería IV · David López Ramírez · Octubre 2026
A4: Qué contiene
A5: Supuestos: todos los datos de entrada en un solo lugar. Cambia aquí y todo el libro se recalcula.
A6: BOM: el «BOM» de un producto sin hardware: cada servicio con su especificación, precio, proveedor y estado de verificación.
A7: Costo IA: llamadas × tokens × precio × usuarios, con la arquitectura real (el LLM solo narra; Stockfish analiza).
A8: Costo unitario: costo por usuario activo a 10 y a 100 usuarios, con overhead (15 %) y contingencia (25 %), y precios cost-plus y value-based.
A9: Flujo de caja: 12 meses, mes a mes, con inversión en el mes 0, VPN al 15 % anual y TIR.
A10: Sensibilidad: cuántos usuarios de pago hacen falta según el precio. Ejercicios: ejercicios 4–9 de la clase (VPN y TIR).
A12: Código de colores
A13: Texto azul: dato de entrada que puedes cambiar. Texto negro: fórmula. Texto verde: referencia a otra hoja.
A14: Fondo amarillo: supuesto clave o dato pendiente. Fondo verde: precio verificado en la página oficial el 08/10/2026.
... A29: los créditos de API se consumen mes a mes hasta agotarse, y el precio cost-plus al público se calcula despejando IVA y comisión exactos.

Sheet Supuestos
A1: Supuestos del modelo
A2: Azul = dato de entrada editable · Negro = fórmula · Amarillo = supuesto clave o por verificar
A3: Supuesto | B3: Valor | C3: Unidad / fuente
A4: Generales
A5: Tipo de cambio | B5: 18.5 | C5: MXN por USD. FIX de Banxico: 17.978 (07/10/2026). Se usa 18.5 como colchón conservador (~3 %)
A6: IVA | B6: 0.16 | C6: Incluido en el precio al consumidor
A7: Comisión de pasarela (%) | B7: 0.036 | C7: VERIFICADO 08/10/2026: stripe.com/mx/pricing, tarjetas nacionales 3.6 % + MXN 3.00; las comisiones excluyen IVA
A8: Comisión de pasarela fija por cobro | B8: 3 | C8: VERIFICADO 08/10/2026: stripe.com/mx/pricing; más IVA sobre la comisión
A9: Overhead | B9: 0.15 | C9: Indicado por el curso
A10: Contingencias | B10: 0.25 | C10: Indicado por el curso (rango 25–40 %)
A11: Tasa de descuento anual | B11: 0.15 | C11: Costo de oportunidad indicado por el curso
A13: Precio y conversión
A14: Precio de suscripción (con IVA) | B14: 59 | C14: MXN/mes; precio recomendado en el modelo económico
A15: Precio value-based (techo) | B15: 79 | C15: MXN/mes; techo estimado en el modelo económico
A16: Margen cost-plus (sobre precio neto) | B16: 0.4 | C16: Indicado por el curso
A17: Conversión de gratis a pago | B17: 0.05 | C17: Escenario conservador: el freemium suele convertir 2–5 %
A18: Mes en que se activa el cobro | B18: 4 | C18: Cuando ya hay patrones para personalizar; nunca justo tras una derrota
A20: Inteligencia artificial (narrador)
A21: Precio de entrada (Claude Haiku 4.5) | B21: 1 | C21: VERIFICADO 08/10/2026: platform.claude.com/docs/en/about-claude/pricing: US$1 / MTok (Haiku 4.5, modelo heredado)
A22: Precio de salida (Claude Haiku 4.5) | B22: 5 | C22: VERIFICADO 08/10/2026: platform.claude.com/docs/en/about-claude/pricing: US$5 / MTok
A23: Tokens de entrada por capítulo | B23: 3000 | C23: Estimado del equipo (arquitectura, semana 5)
A24: Tokens de salida por capítulo | B24: 1000 | C24: Estimado del equipo (arquitectura, semana 5)
A25: Tokens adicionales por español | B25: 0.3 | C25: Indicado por el curso: el español usa ~30 % más tokens
A26: Capítulos al mes por usuario de pago | B26: 20 | C26: Estimado del equipo (≈ 0.7 al día)
A27: Capítulos al mes por usuario gratuito (tope) | B27: 20 | C27: PALANCA: 20 = sin tope (base del profesor); 5 = tope recomendado
A29: Infraestructura cloud
A30: Worker con Stockfish (beta) | B30: 5 | C30: VERIFICADO 08/10/2026: railway.com/pricing: plan Hobby US$5/mes con US$5 de uso incluido; el uso extra se cobra aparte (~US$20 por vCPU al mes en uso continuo)
A31: Supabase (beta) | B31: 0 | C31: VERIFICADO 08/10/2026: supabase.com/pricing: plan Free US$0 (50,000 MAU, 500 MB); pausa proyectos tras 1 semana de inactividad
A32: Meses de worker prepagados en el piloto | B32: 2 | C32: Incluidos en la inversión inicial
A33: Worker a 100 usuarios | B33: 10 | C33: US$/mes; supuesto del modelo económico
A34: Supabase Pro a 100 usuarios | B34: 25 | C34: VERIFICADO 08/10/2026: supabase.com/pricing: plan Pro desde US$25/mes (100,000 MAU, 8 GB)
A36: Inversión del piloto (mes 0)
A37: Incluir cuenta de Google Play (1 = sí, 0 = no) | B37: 1 | C37: DECIDIDO: el piloto incluye cuenta de Google Play (1)
A38: Cuenta de desarrollador de Google Play | B38: 25 | C38: VERIFICADO 08/10/2026: support.google.com/googleplay/android-developer: pago único de US$25
A39: Dominio .com (1 año) | B39: 11.08 | C39: VERIFICADO 08/10/2026: porkbun.com: .com US$11.08 registro y renovación (.mx: US$35.57)
A40: Créditos de API del LLM (prepago) | B40: 20 | C40: US$; se consumen mes a mes hasta agotarse
A42: B2B2C (academias y entrenadores)
A43: Licencias de academia activas | B43: 0 | C43: DECIDIDO: 0 en el escenario base (no se cuenta un ingreso sin firmar); meta: 1 academia piloto desde el mes 7, sin dashboard
A44: Precio por licencia (sin IVA) | B44: 1000 | C44: MXN/mes; rango sugerido $500–1,500
A45: Mes de inicio de las licencias | B45: 7 | C45: Mes objetivo de la academia piloto (tras 3 meses de datos B2C)
...

Sheet BOM
A1: «BOM» de Zaqora: servicios por usuario y costos fijos
A2: Zaqora no tiene hardware: cada «componente» es un servicio. Precios verificados en las páginas oficiales el 08/10/2026 (fondo verde).
A4: Componente | B4: Especificación | C4: Proveedor | D4: Precio unitario | E4: Unidad | F4: Precio en MXN | G4: Tipo | H4: Fuente / estado | I4: Tiempo de entrega (alta o activación)
A5: LLM narrador (entrada) | B5: Claude Haiku 4.5, salida JSON; solo narra | C5: Anthropic | D5: =Supuestos!$B$21 -> 1 | E5: US$ / millón de tokens | F5: =IF(D5="","",D5*Supuestos!$B$5) -> 18.5 | G5: Variable | H5: VERIFICADO 08/10/2026: platform.claude.com (precio de lista) | I5: Inmediato (clave de API al crear la cuenta)
A6: LLM narrador (salida) | B6: Claude Haiku 4.5 | C6: Anthropic | D6: =Supuestos!$B$22 -> 5 | E6: US$ / millón de tokens | F6: =IF(D6="","",D6*Supuestos!$B$5) -> 92.5 | G6: Variable | H6: VERIFICADO 08/10/2026: platform.claude.com (precio de lista) | I6: Inmediato (clave de API al crear la cuenta)
A7: Worker de análisis | B7: Python + Stockfish, compartido | C7: Railway (plan Hobby) | D7: =Supuestos!$B$30 -> 5 | E7: US$ / mes | F7: =IF(D7="","",D7*Supuestos!$B$5) -> 92.5 | G7: Fijo | H7: VERIFICADO 08/10/2026: railway.com/pricing (Hobby, incluye US$5 de uso) | I7: Inmediato (despliegue en minutos)
A8: Base de datos y autenticación | B8: Postgres + Auth + Edge Functions (beta) | C8: Supabase (gratuito) | D8: =Supuestos!$B$31 -> 0 | E8: US$ / mes | F8: =IF(D8="","",D8*Supuestos!$B$5) -> 0 | G8: Fijo | H8: VERIFICADO 08/10/2026: supabase.com/pricing (Free; pausa tras 1 semana sin uso) | I8: Inmediato
A9: Base de datos a escala | B9: Supabase Pro (100+ usuarios) | C9: Supabase | D9: =Supuestos!$B$34 -> 25 | E9: US$ / mes | F9: =IF(D9="","",D9*Supuestos!$B$5) -> 462.5 | G9: Fijo | H9: VERIFICADO 08/10/2026: supabase.com/pricing | I9: Inmediato (cambio de plan)
A10: Dominio .com | B10: Dominio para la landing | C10: Porkbun | D10: =Supuestos!$B$39 -> 11.08 | E10: US$ / año | F10: =IF(D10="","",D10*Supuestos!$B$5) -> 204.98 | G10: Fijo | H10: VERIFICADO 08/10/2026: porkbun.com (.com US$11.08 registro y renovación) | I10: Minutos (registro y DNS)
A11: Cuenta de Google Play | B11: Solo si se publica como TWA | C11: Google | D11: =Supuestos!$B$38 -> 25 | E11: US$ pago único | F11: =IF(D11="","",D11*Supuestos!$B$5) -> 462.5 | G11: Fijo | H11: VERIFICADO 08/10/2026: support.google.com/googleplay (pago único) | I11: Supuesto: 1–2 semanas. Exige verificación de identidad (ID oficial y tarjeta); Google no publica un plazo
A12: Pasarela de pago (%) | B12: Cobro web con tarjeta | C12: Stripe México | D12: =Supuestos!$B$7 -> 0.036 | E12: % por cobro | F12: - | G12: Variable | H12: VERIFICADO 08/10/2026: stripe.com/mx/pricing (excluye IVA) | I12: Inmediato en modo de prueba; cobros reales tras verificar la cuenta (KYC)
A13: Pasarela de pago (fija) | B13: Cobro web con tarjeta | C13: Stripe México | D13: =Supuestos!$B$8 -> 3 | E13: MXN por cobro | F13: =D13 -> 3 | G13: Variable | H13: VERIFICADO 08/10/2026: stripe.com/mx/pricing (excluye IVA) | I13: Igual que la fila anterior
A14: Hosting de la PWA y la landing | B14: Sitio estático / PWA y landing | C14: Cloudflare Pages (plan gratuito) | D14: 0 | E14: US$ / mes | F14: =IF(D14="","",D14*Supuestos!$B$5) -> 0 | G14: Fijo | H14: VERIFICADO 08/10/2026: developers.cloudflare.com/pages/platform/limits (500 builds/mes, 20,000 archivos). Vercel Hobby se descartó: solo uso personal no comercial | I14: Inmediato (despliegue en minutos)
A15: LLM alternativo (entrada) | B15: Claude Haiku 5.5, prompts ≤ 100k tokens; tokenizador nuevo (~30 % más tokens) | C15: Anthropic | D15: 0.1 | E15: US$ / millón de tokens | F15: =D15*Supuestos!$B$5 -> 1.85 | G15: Variable | H15: VERIFICADO 08/10/2026: platform.claude.com · alternativa a evaluar | I15: Inmediato
A16: LLM alternativo (salida) | B16: Claude Haiku 5.5 | C16: Anthropic | D16: 0.5 | E16: US$ / millón de tokens | F16: =D16*Supuestos!$B$5 -> 9.25 | G16: Variable | H16: VERIFICADO 08/10/2026: platform.claude.com · alternativa a evaluar | I16: Inmediato
A17: Descuento Batch API (Haiku 4.5) | B17: Capítulos no urgentes: entrada / salida | C17: Anthropic | D17: 0.5 | E17: US$ / millón (entrada); salida US$2.50 | F17: =D17*Supuestos!$B$5 -> 9.25 | G17: Variable | H17: VERIFICADO 08/10/2026: platform.claude.com (50 % de descuento) | I17: Inmediato; los resultados del lote llegan en horas
A19: Los precios activos del modelo se editan en la hoja Supuestos (texto verde = viene de otra hoja). Filas 15–17: alternativas verificadas, no usadas en el escenario base. En servicios, el «tiempo de entrega» es el tiempo de alta o activación.

Sheet Costo IA
A1: Costo mensual de la IA
A2: Costo mensual = llamadas al mes × (tokens de entrada × precio + tokens de salida × precio) × (1 + 30 % por español) × usuarios
A4: Escenario | B4: Llamadas al día | C4: Tokens entrada | D4: Tokens salida | E4: Costo por usuario (US$) | F4: Costo por usuario (MXN) | G4: Usuarios | H4: Costo mensual (MXN)
A5: Usuario de pago, 20 beta | B5: =Supuestos!$B$26/30 -> 0.66666667 | C5: =Supuestos!$B$23 -> 3000 | D5: =Supuestos!$B$24 -> 1000 | E5: =B5*30*Supuestos!$B$48 -> 0.208 | F5: =E5*Supuestos!$B$5 -> 3.848 | G5: 20 | H5: =F5*G5 -> 76.96
A6: Usuario de pago, 100 usuarios | B6: =Supuestos!$B$26/30 -> 0.66666667 | C6: =Supuestos!$B$23 -> 3000 | D6: =Supuestos!$B$24 -> 1000 | E6: =B6*30*Supuestos!$B$48 -> 0.208 | F6: =E6*Supuestos!$B$5 -> 3.848 | G6: 100 | H6: =F6*G6 -> 384.8
A7: Usuario de pago, 1,200 clientes (SOM) | B7: =Supuestos!$B$26/30 -> 0.66666667 | C7: =Supuestos!$B$23 -> 3000 | D7: =Supuestos!$B$24 -> 1000 | E7: =B7*30*Supuestos!$B$48 -> 0.208 | F7: =E7*Supuestos!$B$5 -> 3.848 | G7: 1200 | H7: =F7*G7 -> 4617.6
A8: Usuario gratuito (con el tope de Supuestos) | B8: =Supuestos!$B$27/30 -> 0.66666667 | C8: =Supuestos!$B$23 -> 3000 | D8: =Supuestos!$B$24 -> 1000 | E8: =B8*30*Supuestos!$B$48 -> 0.208 | F8: =E8*Supuestos!$B$5 -> 3.848 | G8: 19 | H8: =F8*G8 -> 73.112
A9: Usuario gratuito con tope de 5 capítulos | B9: =5/30 -> 0.16666667 | C9: =Supuestos!$B$23 -> 3000 | D9: =Supuestos!$B$24 -> 1000 | E9: =B9*30*Supuestos!$B$48 -> 0.052 | F9: =E9*Supuestos!$B$5 -> 0.962 | G9: 19 | H9: =F9*G9 -> 18.278
A11: Las 19 cuentas gratuitas corresponden a un suscriptor con 5 % de conversión (1 de pago por cada 19 gratuitos).
A12: Carga de IA de los gratuitos por cada suscriptor (sin tope) | H12: =H8 -> 73.112
A13: Carga de IA de los gratuitos por cada suscriptor (tope de 5) | H13: =H9 -> 18.278
A14: Ingreso neto que deja cada suscriptor | H14: =Supuestos!$B$51 -> 44.918229

Sheet Costo unitario
A1: Costo unitario y precio de venta
A2: Costo por usuario activo al mes. Overhead sobre el costo directo; contingencia sobre (costo directo + overhead).
A4: Concepto | B4: 10 usuarios | C4: 100 usuarios | D4: Cómo se calcula
A5: Usuarios activos | B5: 10 | C5: 100 | D5: Volumen de prueba de mercado y de escala inicial
A6: Cloud total (US$/mes) | B6: =Supuestos!$B$30+Supuestos!$B$31 -> 5 | C6: =Supuestos!$B$33+Supuestos!$B$34 -> 35 | D6: Worker + Supabase de cada escala
A7: Cloud por usuario | B7: =B6*Supuestos!$B$5/B5 -> 9.25 | C7: =C6*Supuestos!$B$5/C5 -> 6.475 | D7: Costo fijo repartido entre usuarios
A8: IA por usuario | B8: =Supuestos!$B$49 -> 3.848 | C8: =Supuestos!$B$49 -> 3.848 | D8: Hoja Supuestos (uso de un usuario de pago)
A9: Costo directo | B9: =B7+B8 -> 13.098 | C9: =C7+C8 -> 10.323 | D9: Cloud + IA
A10: Overhead | B10: =B9*Supuestos!$B$9 -> 1.9647 | C10: =C9*Supuestos!$B$9 -> 1.54845 | D10: 15 % del costo directo
A11: Contingencia | B11: =(B9+B10)*Supuestos!$B$10 -> 3.765675 | C11: =(C9+C10)*Supuestos!$B$10 -> 2.9678625 | D11: 25 % de (directo + overhead)
A12: COSTO UNITARIO | B12: =B9+B10+B11 -> 18.828375 | C12: =C9+C10+C11 -> 14.839313 | D12: MXN por usuario activo al mes
A13: Peso de la IA en el costo directo | B13: =IF(B9=0,0,B8/B9) -> 0.29378531 | C13: =IF(C9=0,0,C8/C9) -> 0.37275986
A14: Peso del cloud en el costo directo | B14: =IF(B9=0,0,B7/B9) -> 0.70621469 | C14: =IF(C9=0,0,C7/C9) -> 0.62724014
A16: Precio cost-plus neto (40 % de margen) | B16: =B12/(1-Supuestos!$B$16) -> 31.380625 | C16: =C12/(1-Supuestos!$B$16) -> 24.732188 | D16: Costo unitario / (1 − margen)
A17: Precio cost-plus al público | B17: =(B16+Supuestos!$B$8*(1+Supuestos!$B$6))/(1/(1+Supuestos!$B$6)-Supuestos!$B$7*(1+Supuestos!$B$6)) -> 42.496945 | C17: =(C16+Supuestos!$B$8*(1+Supuestos!$B$6))/(1/(1+Supuestos!$B$6)-Supuestos!$B$7*(1+Supuestos!$B$6)) -> 34.392148 | D17: Precio con IVA que deja ese neto tras la comisión
A18: Precio value-based (techo) | B18: =Supuestos!$B$15 -> 79 | C18: =Supuestos!$B$15 -> 79 | D18: Estimado; disposición de pago no verificada
A19: Precio recomendado (con IVA) | B19: =Supuestos!$B$14 -> 59 | C19: =Supuestos!$B$14 -> 59 | D19: Entre cost-plus y value-based
A20: Ingreso neto por suscriptor | B20: =Supuestos!$B$51 -> 44.918229 | C20: =Supuestos!$B$51 -> 44.918229 | D20: Sin IVA ni comisión
A21: Ingreso neto / costo unitario | B21: =IF(B12=0,0,B20/B12) -> 2.3856668 | C21: =IF(C12=0,0,C20/C12) -> 3.0269751 | D21: Veces que el ingreso cubre el costo
A22: ¿Precio recomendado entre cost-plus y value-based? | B22: =IF(AND(B19>=B17,B19<=B18),"Sí","No") -> Sí | C22: =IF(AND(C19>=C17,C19<=C18),"Sí","No") -> Sí | D22: Validación pedida por el curso

Sheet Flujo de caja
A1: Flujo de caja a 12 meses (MXN)
A2: Usuarios activos en azul: plan de volumen del año 1 (prueba de mercado con 20 usuarios beta). Todo lo demás son fórmulas.
A4: Mes | B4: Usuarios activos | C4: Usuarios de pago | D4: Usuarios gratuitos | E4: Ingreso suscripciones | F4: Ingreso licencias | G4: Ingreso total | H4: Cloud | I4: IA consumida | J4: IA acumulada | K4: IA pagada (tras créditos) | L4: Operación | M4: Overhead + contingencia | N4: Inversión inicial | O4: Egresos totales | P4: Flujo neto | Q4: Flujo acumulado | R4: Factor de descuento | S4: Flujo descontado | T4: Mes con flujo positivo
A5: 0 | B5: 0 | C5: =IF(A5>=Supuestos!$B$18,INT(B5*Supuestos!$B$17),0) -> 0 | D5: =B5-C5 -> 0 | E5: =C5*Supuestos!$B$51 -> 0 | F5: =IF(AND(A5>0,A5>=Supuestos!$B$45),Supuestos!$B$43*Supuestos!$B$44,0) -> 0 | G5: =E5+F5 -> 0 | H5: =IF(OR(A5=0,A5<=Supuestos!$B$32),0,(Supuestos!$B$30+Supuestos!$B$31)*Supuestos!$B$5) -> 0 | I5: =C5*Supuestos!$B$49+D5*Supuestos!$B$50 -> 0 | J5: =I5 -> 0 | K5: =MAX(0,J5-Supuestos!$B$53) -> 0 | L5: =H5+K5 -> 0 | M5: =L5*(Supuestos!$B$55-1) -> 0 | N5: =IF(A5=0,Supuestos!$B$54,0) -> 1222.48 | O5: =L5+M5+N5 -> 1222.48 | P5: =G5-O5 -> -1222.48 | Q5: =P5 -> -1222.48 | R5: =1/(1+Supuestos!$B$52)^A5 -> 1 | S5: =P5*R5 -> -1222.48 | T5: =IF(AND(A5>0,P5>0),A5,"")
A6: 1 | B6: 5 | C6: =IF(A6>=Supuestos!$B$18,INT(B6*Supuestos!$B$17),0) -> 0 | D6: =B6-C6 -> 5 | E6: =C6*Supuestos!$B$51 -> 0 | F6: =IF(AND(A6>0,A6>=Supuestos!$B$45),Supuestos!$B$43*Supuestos!$B$44,0) -> 0 | G6: =E6+F6 -> 0 | H6: =IF(OR(A6=0,A6<=Supuestos!$B$32),0,(Supuestos!$B$30+Supuestos!$B$31)*Supuestos!$B$5) -> 0 | I6: =C6*Supuestos!$B$49+D6*Supuestos!$B$50 -> 19.24 | J6: =J5+I6 -> 19.24 | K6: =MAX(0,J6-Supuestos!$B$53)-MAX(0,J5-Supuestos!$B$53) -> 0 | L6: =H6+K6 -> 0 | M6: =L6*(Supuestos!$B$55-1) -> 0 | N6: =IF(A6=0,Supuestos!$B$54,0) -> 0 | O6: =L6+M6+N6 -> 0 | P6: =G6-O6 -> 0 | Q6: =Q5+P6 -> -1222.48 | R6: =1/(1+Supuestos!$B$52)^A6 -> 0.98842073 | S6: =P6*R6 -> 0 | T6: =IF(AND(A6>0,P6>0),A6,"")
A7: 2 | B7: 10 | C7: =IF(A7>=Supuestos!$B$18,INT(B7*Supuestos!$B$17),0) -> 0 | D7: =B7-C7 -> 10 | E7: =C7*Supuestos!$B$51 -> 0 | F7: =IF(AND(A7>0,A7>=Supuestos!$B$45),Supuestos!$B$43*Supuestos!$B$44,0) -> 0 | G7: =E7+F7 -> 0 | H7: =IF(OR(A7=0,A7<=Supuestos!$B$32),0,(Supuestos!$B$30+Supuestos!$B$31)*Supuestos!$B$5) -> 0 | I7: =C7*Supuestos!$B$49+D7*Supuestos!$B$50 -> 38.48 | J7: =J6+I7 -> 57.72 | K7: =MAX(0,J7-Supuestos!$B$53)-MAX(0,J6-Supuestos!$B$53) -> 0 | L7: =H7+K7 -> 0 | M7: =L7*(Supuestos!$B$55-1) -> 0 | N7: =IF(A7=0,Supuestos!$B$54,0) -> 0 | O7: =L7+M7+N7 -> 0 | P7: =G7-O7 -> 0 | Q7: =Q6+P7 -> -1222.48 | R7: =1/(1+Supuestos!$B$52)^A7 -> 0.97697555 | S7: =P7*R7 -> 0 | T7: =IF(AND(A7>0,P7>0),A7,"")
A8: 3 | B8: 15 | C8: =IF(A8>=Supuestos!$B$18,INT(B8*Supuestos!$B$17),0) -> 0 | D8: =B8-C8 -> 15 | E8: =C8*Supuestos!$B$51 -> 0 | F8: =IF(AND(A8>0,A8>=Supuestos!$B$45),Supuestos!$B$43*Supuestos!$B$44,0) -> 0 | G8: =E8+F8 -> 0 | H8: =IF(OR(A8=0,A8<=Supuestos!$B$32),0,(Supuestos!$B$30+Supuestos!$B$31)*Supuestos!$B$5) -> 92.5 | I8: =C8*Supuestos!$B$49+D8*Supuestos!$B$50 -> 57.72 | J8: =J7+I8 -> 115.44 | K8: =MAX(0,J8-Supuestos!$B$53)-MAX(0,J7-Supuestos!$B$53) -> 0 | L8: =H8+K8 -> 92.5 | M8: =L8*(Supuestos!$B$55-1) -> 40.46875 | N8: =IF(A8=0,Supuestos!$B$54,0) -> 0 | O8: =L8+M8+N8 -> 132.96875 | P8: =G8-O8 -> -132.96875 | Q8: =Q7+P8 -> -1355.4488 | R8: =1/(1+Supuestos!$B$52)^A8 -> 0.96566289 | S8: =P8*R8 -> -128.40299 | T8: =IF(AND(A8>0,P8>0),A8,"")
A9: 4 | B9: 20 | C9: =IF(A9>=Supuestos!$B$18,INT(B9*Supuestos!$B$17),0) -> 1 | D9: =B9-C9 -> 19 | E9: =C9*Supuestos!$B$51 -> 44.918229 | F9: =IF(AND(A9>0,A9>=Supuestos!$B$45),Supuestos!$B$43*Supuestos!$B$44,0) -> 0 | G9: =E9+F9 -> 44.918229 | H9: =IF(OR(A9=0,A9<=Supuestos!$B$32),0,(Supuestos!$B$30+Supuestos!$B$31)*Supuestos!$B$5) -> 92.5 | I9: =C9*Supuestos!$B$49+D9*Supuestos!$B$50 -> 76.96 | J9: =J8+I9 -> 192.4 | K9: =MAX(0,J9-Supuestos!$B$53)-MAX(0,J8-Supuestos!$B$53) -> 0 | L9: =H9+K9 -> 92.5 | M9: =L9*(Supuestos!$B$55-1) -> 40.46875 | N9: =IF(A9=0,Supuestos!$B$54,0) -> 0 | O9: =L9+M9+N9 -> 132.96875 | P9: =G9-O9 -> -88.050521 | Q9: =Q8+P9 -> -1443.4993 | R9: =1/(1+Supuestos!$B$52)^A9 -> 0.95448122 | S9: =P9*R9 -> -84.042568 | T9: =IF(AND(A9>0,P9>0),A9,"")
A10: 5 | B10: 20 | C10: =IF(A10>=Supuestos!$B$18,INT(B10*Supuestos!$B$17),0) -> 1 | D10: =B10-C10 -> 19 | E10: =C10*Supuestos!$B$51 -> 44.918229 | F10: =IF(AND(A10>0,A10>=Supuestos!$B$45),Supuestos!$B$43*Supuestos!$B$44,0) -> 0 | G10: =E10+F10 -> 44.918229 | H10: =IF(OR(A10=0,A10<=Supuestos!$B$32),0,(Supuestos!$B$30+Supuestos!$B$31)*Supuestos!$B$5) -> 92.5 | I10: =C10*Supuestos!$B$49+D10*Supuestos!$B$50 -> 76.96 | J10: =J9+I10 -> 269.36 | K10: =MAX(0,J10-Supuestos!$B$53)-MAX(0,J9-Supuestos!$B$53) -> 0 | L10: =H10+K10 -> 92.5 | M10: =L10*(Supuestos!$B$55-1) -> 40.46875 | N10: =IF(A10=0,Supuestos!$B$54,0) -> 0 | O10: =L10+M10+N10 -> 132.96875 | P10: =G10-O10 -> -88.050521 | Q10: =Q9+P10 -> -1531.5498 | R10: =1/(1+Supuestos!$B$52)^A10 -> 0.94342902 | S10: =P10*R10 -> -83.069417 | T10: =IF(AND(A10>0,P10>0),A10,"")
A11: 6 | B11: 20 | C11: =IF(A11>=Supuestos!$B$18,INT(B11*Supuestos!$B$17),0) -> 1 | D11: =B11-C11 -> 19 | E11: =C11*Supuestos!$B$51 -> 44.918229 | F11: =IF(AND(A11>0,A11>=Supuestos!$B$45),Supuestos!$B$43*Supuestos!$B$44,0) -> 0 | G11: =E11+F11 -> 44.918229 | H11: =IF(OR(A11=0,A11<=Supuestos!$B$32),0,(Supuestos!$B$30+Supuestos!$B$31)*Supuestos!$B$5) -> 92.5 | I11: =C11*Supuestos!$B$49+D11*Supuestos!$B$50 -> 76.96 | J11: =J10+I11 -> 346.32 | K11: =MAX(0,J11-Supuestos!$B$53)-MAX(0,J10-Supuestos!$B$53) -> 0 | L11: =H11+K11 -> 92.5 | M11: =L11*(Supuestos!$B$55-1) -> 40.46875 | N11: =IF(A11=0,Supuestos!$B$54,0) -> 0 | O11: =L11+M11+N11 -> 132.96875 | P11: =G11-O11 -> -88.050521 | Q11: =Q10+P11 -> -1619.6003 | R11: =1/(1+Supuestos!$B$52)^A11 -> 0.93250481 | S11: =P11*R11 -> -82.107534 | T11: =IF(AND(A11>0,P11>0),A11,"")
A12: 7 | B12: 20 | C12: =IF(A12>=Supuestos!$B$18,INT(B12*Supuestos!$B$17),0) -> 1 | D12: =B12-C12 -> 19 | E12: =C12*Supuestos!$B$51 -> 44.918229 | F12: =IF(AND(A12>0,A12>=Supuestos!$B$45),Supuestos!$B$43*Supuestos!$B$44,0) -> 0 | G12: =E12+F12 -> 44.918229 | H12: =IF(OR(A12=0,A12<=Supuestos!$B$32),0,(Supuestos!$B$30+Supuestos!$B$31)*Supuestos!$B$5) -> 92.5 | I12: =C12*Supuestos!$B$49+D12*Supuestos!$B$50 -> 76.96 | J12: =J11+I12 -> 423.28 | K12: =MAX(0,J12-Supuestos!$B$53)-MAX(0,J11-Supuestos!$B$53) -> 53.28 | L12: =H12+K12 -> 145.78 | M12: =L12*(Supuestos!$B$55-1) -> 63.77875 | N12: =IF(A12=0,Supuestos!$B$54,0) -> 0 | O12: =L12+M12+N12 -> 209.55875 | P12: =G12-O12 -> -164.64052 | Q12: =Q11+P12 -> -1784.2408 | R12: =1/(1+Supuestos!$B$52)^A12 -> 0.92170709 | S12: =P12*R12 -> -151.75033 | T12: =IF(AND(A12>0,P12>0),A12,"")
A13: 8 | B13: 20 | C13: =IF(A13>=Supuestos!$B$18,INT(B13*Supuestos!$B$17),0) -> 1 | D13: =B13-C13 -> 19 | E13: =C13*Supuestos!$B$51 -> 44.918229 | F13: =IF(AND(A13>0,A13>=Supuestos!$B$45),Supuestos!$B$43*Supuestos!$B$44,0) -> 0 | G13: =E13+F13 -> 44.918229 | H13: =IF(OR(A13=0,A13<=Supuestos!$B$32),0,(Supuestos!$B$30+Supuestos!$B$31)*Supuestos!$B$5) -> 92.5 | I13: =C13*Supuestos!$B$49+D13*Supuestos!$B$50 -> 76.96 | J13: =J12+I13 -> 500.24 | K13: =MAX(0,J13-Supuestos!$B$53)-MAX(0,J12-Supuestos!$B$53) -> 76.96 | L13: =H13+K13 -> 169.46 | M13: =L13*(Supuestos!$B$55-1) -> 74.13875 | N13: =IF(A13=0,Supuestos!$B$54,0) -> 0 | O13: =L13+M13+N13 -> 243.59875 | P13: =G13-O13 -> -198.68052 | Q13: =Q12+P13 -> -1982.9214 | R13: =1/(1+Supuestos!$B$52)^A13 -> 0.91103439 | S13: =P13*R13 -> -181.00479 | T13: =IF(AND(A13>0,P13>0),A13,"")
A14: 9 | B14: 20 | C14: =IF(A14>=Supuestos!$B$18,INT(B14*Supuestos!$B$17),0) -> 1 | D14: =B14-C14 -> 19 | E14: =C14*Supuestos!$B$51 -> 44.918229 | F14: =IF(AND(A14>0,A14>=Supuestos!$B$45),Supuestos!$B$43*Supuestos!$B$44,0) -> 0 | G14: =E14+F14 -> 44.918229 | H14: =IF(OR(A14=0,A14<=Supuestos!$B$32),0,(Supuestos!$B$30+Supuestos!$B$31)*Supuestos!$B$5) -> 92.5 | I14: =C14*Supuestos!$B$49+D14*Supuestos!$B$50 -> 76.96 | J14: =J13+I14 -> 577.2 | K14: =MAX(0,J14-Supuestos!$B$53)-MAX(0,J13-Supuestos!$B$53) -> 76.96 | L14: =H14+K14 -> 169.46 | M14: =L14*(Supuestos!$B$55-1) -> 74.13875 | N14: =IF(A14=0,Supuestos!$B$54,0) -> 0 | O14: =L14+M14+N14 -> 243.59875 | P14: =G14-O14 -> -198.68052 | Q14: =Q13+P14 -> -2181.6019 | R14: =1/(1+Supuestos!$B$52)^A14 -> 0.90048528 | S14: =P14*R14 -> -178.90889 | T14: =IF(AND(A14>0,P14>0),A14,"")
A15: 10 | B15: 20 | C15: =IF(A15>=Supuestos!$B$18,INT(B15*Supuestos!$B$17),0) -> 1 | D15: =B15-C15 -> 19 | E15: =C15*Supuestos!$B$51 -> 44.918229 | F15: =IF(AND(A15>0,A15>=Supuestos!$B$45),Supuestos!$B$43*Supuestos!$B$44,0) -> 0 | G15: =E15+F15 -> 44.918229 | H15: =IF(OR(A15=0,A15<=Supuestos!$B$32),0,(Supuestos!$B$30+Supuestos!$B$31)*Supuestos!$B$5) -> 92.5 | I15: =C15*Supuestos!$B$49+D15*Supuestos!$B$50 -> 76.96 | J15: =J14+I15 -> 654.16 | K15: =MAX(0,J15-Supuestos!$B$53)-MAX(0,J14-Supuestos!$B$53) -> 76.96 | L15: =H15+K15 -> 169.46 | M15: =L15*(Supuestos!$B$55-1) -> 74.13875 | N15: =IF(A15=0,Supuestos!$B$54,0) -> 0 | O15: =L15+M15+N15 -> 243.59875 | P15: =G15-O15 -> -198.68052 | Q15: =Q14+P15 -> -2380.2824 | R15: =1/(1+Supuestos!$B$52)^A15 -> 0.89005832 | S15: =P15*R15 -> -176.83725 | T15: =IF(AND(A15>0,P15>0),A15,"")
A16: 11 | B16: 20 | C16: =IF(A16>=Supuestos!$B$18,INT(B16*Supuestos!$B$17),0) -> 1 | D16: =B16-C16 -> 19 | E16: =C16*Supuestos!$B$51 -> 44.918229 | F16: =IF(AND(A16>0,A16>=Supuestos!$B$45),Supuestos!$B$43*Supuestos!$B$44,0) -> 0 | G16: =E16+F16 -> 44.918229 | H16: =IF(OR(A16=0,A16<=Supuestos!$B$32),0,(Supuestos!$B$30+Supuestos!$B$31)*Supuestos!$B$5) -> 92.5 | I16: =C16*Supuestos!$B$49+D16*Supuestos!$B$50 -> 76.96 | J16: =J15+I16 -> 731.12 | K16: =MAX(0,J16-Supuestos!$B$53)-MAX(0,J15-Supuestos!$B$53) -> 76.96 | L16: =H16+K16 -> 169.46 | M16: =L16*(Supuestos!$B$55-1) -> 74.13875 | N16: =IF(A16=0,Supuestos!$B$54,0) -> 0 | O16: =L16+M16+N16 -> 243.59875 | P16: =G16-O16 -> -198.68052 | Q16: =Q15+P16 -> -2578.9629 | R16: =1/(1+Supuestos!$B$52)^A16 -> 0.8797521 | S16: =P16*R16 -> -174.78961 | T16: =IF(AND(A16>0,P16>0),A16,"")
A17: 12 | B17: 20 | C17: =IF(A17>=Supuestos!$B$18,INT(B17*Supuestos!$B$17),0) -> 1 | D17: =B17-C17 -> 19 | E17: =C17*Supuestos!$B$51 -> 44.918229 | F17: =IF(AND(A17>0,A17>=Supuestos!$B$45),Supuestos!$B$43*Supuestos!$B$44,0) -> 0 | G17: =E17+F17 -> 44.918229 | H17: =IF(OR(A17=0,A17<=Supuestos!$B$32),0,(Supuestos!$B$30+Supuestos!$B$31)*Supuestos!$B$5) -> 92.5 | I17: =C17*Supuestos!$B$49+D17*Supuestos!$B$50 -> 76.96 | J17: =J16+I17 -> 808.08 | K17: =MAX(0,J17-Supuestos!$B$53)-MAX(0,J16-Supuestos!$B$53) -> 76.96 | L17: =H17+K17 -> 169.46 | M17: =L17*(Supuestos!$B$55-1) -> 74.13875 | N17: =IF(A17=0,Supuestos!$B$54,0) -> 0 | O17: =L17+M17+N17 -> 243.59875 | P17: =G17-O17 -> -198.68052 | Q17: =Q16+P17 -> -2777.6434 | R17: =1/(1+Supuestos!$B$52)^A17 -> 0.86956522 | S17: =P17*R17 -> -172.76567 | T17: =IF(AND(A17>0,P17>0),A17,"")
A18: Total | E18: =SUM(E5:E17) -> 404.26406 | F18: =SUM(F5:F17) -> 0 | G18: =SUM(G5:G17) -> 404.26406 | H18: =SUM(H5:H17) -> 925 | I18: =SUM(I5:I17) -> 808.08 | K18: =SUM(K5:K17) -> 438.08 | L18: =SUM(L5:L17) -> 1363.08 | M18: =SUM(M5:M17) -> 596.3475 | N18: =SUM(N5:N17) -> 1222.48 | O18: =SUM(O5:O17) -> 3181.9075 | P18: =SUM(P5:P17) -> -2777.6434 | S18: =SUM(S5:S17) -> -2636.159
A20: Resultados
A21: VPN a 12 meses (tasa anual del 15 %) | F21: =SUM(S5:S17) -> -2636.159
A22: Veredicto | F22: =IF(F21>0,"Viable",IF(F21>-0.05*N5,"Marginalmente viable","Inviable como negocio en 12 meses")) -> Inviable como negocio en 12 meses
A23: TIR mensual | F23: =IFERROR(IRR(P5:P17),"No existe: los flujos no cambian de signo") -> No existe: los flujos no cambian de signo
A24: TIR anualizada | F24: =IFERROR((1+IRR(P5:P17))^12-1,"No existe") -> No existe
A25: Primer mes con flujo positivo | F25: =IF(COUNT(T6:T17)=0,"Ninguno en 12 meses",MIN(T6:T17)) -> Ninguno en 12 meses
A26: Flujo acumulado al mes 12 | F26: =Q17 -> -2777.6434
A27: Inversión acumulada más profunda (valle de caja) | F27: =MIN(Q5:Q17) -> -2777.6434
A28: Suscriptores necesarios todo el año desde el paywall | F28: =ROUNDUP((O18-F18)/(Supuestos!$B$51*(13-Supuestos!$B$18)),0) -> 8
A29: Conversión que implica sobre los activos del mes 12 | F29: =IF(B17=0,0,F28/B17) -> 0.4
A30: Suscriptores para cubrir solo la operación del mes 12 | F30: =ROUNDUP(O17/Supuestos!$B$51,0) -> 6

Sheet Sensibilidad
A1: Sensibilidad al precio
A2: Cuántos suscriptores cubren la operación mensual (mes 12 del flujo) según el precio, y qué conversión implica sobre 20 y 100 usuarios.
A4: Precio con IVA (MXN/mes) | B4: Ingreso neto | C4: Suscriptores para cubrir la operación | D4: Conversión necesaria con 20 activos | E4: Conversión necesaria con 100 activos
A5: 39 | B5: =A5/(1+Supuestos!$B$6)-(A5*Supuestos!$B$7+Supuestos!$B$8)*(1+Supuestos!$B$6) -> 28.51205 | C5: =ROUNDUP('Flujo de caja'!$O$17/B5,0) -> 9 | D5: =C5/20 -> 0.45 | E5: =C5/100 -> 0.09
A6: 49 | B6: =A6/(1+Supuestos!$B$6)-(A6*Supuestos!$B$7+Supuestos!$B$8)*(1+Supuestos!$B$6) -> 36.715139 | C6: =ROUNDUP('Flujo de caja'!$O$17/B6,0) -> 7 | D6: =C6/20 -> 0.35 | E6: =C6/100 -> 0.07
A7: 59 | B7: =A7/(1+Supuestos!$B$6)-(A7*Supuestos!$B$7+Supuestos!$B$8)*(1+Supuestos!$B$6) -> 44.918229 | C7: =ROUNDUP('Flujo de caja'!$O$17/B7,0) -> 6 | D7: =C7/20 -> 0.3 | E7: =C7/100 -> 0.06
A8: 79 | B8: =A8/(1+Supuestos!$B$6)-(A8*Supuestos!$B$7+Supuestos!$B$8)*(1+Supuestos!$B$6) -> 61.324408 | C8: =ROUNDUP('Flujo de caja'!$O$17/B8,0) -> 4 | D8: =C8/20 -> 0.2 | E8: =C8/100 -> 0.04
A9: 99 | B9: =A9/(1+Supuestos!$B$6)-(A9*Supuestos!$B$7+Supuestos!$B$8)*(1+Supuestos!$B$6) -> 77.730588 | C9: =ROUNDUP('Flujo de caja'!$O$17/B9,0) -> 4 | D9: =C9/20 -> 0.2 | E9: =C9/100 -> 0.04
A10: 149 | B10: =A10/(1+Supuestos!$B$6)-(A10*Supuestos!$B$7+Supuestos!$B$8)*(1+Supuestos!$B$6) -> 118.74604 | C10: =ROUNDUP('Flujo de caja'!$O$17/B10,0) -> 3 | D10: =C10/20 -> 0.15 | E10: =C10/100 -> 0.03
A11: 300 | B11: =A11/(1+Supuestos!$B$6)-(A11*Supuestos!$B$7+Supuestos!$B$8)*(1+Supuestos!$B$6) -> 242.61269 | C11: =ROUNDUP('Flujo de caja'!$O$17/B11,0) -> 2 | D11: =C11/20 -> 0.1 | E11: =C11/100 -> 0.02
A13: La operación del mes 12 incluye cloud, IA tras créditos, overhead y contingencia; no incluye sueldos del equipo.

Sheet Ejercicios
A1: Ejercicios 4–9: VPN y TIR (USD)
A2: Flujos y tasas en azul. VPN = flujo del año 0 + VPN(tasa; flujos 1..n). TIR interpolada con las tasas r1 y r2; TIR exacta con la función TIR.
A4: Ejercicio 4 — InnovaTech
A5: Concepto | B5: Año 0 | C5: Año 1 | D5: Año 2 | E5: Año 3 | F5: Año 4 | G5: Año 5 | H5: Año 6
A6: Flujo | B6: -250000 | C6: 60000 | D6: 60000 | E6: 60000 | F6: 60000 | G6: 60000 | H6: 60000
A7: Tasa de descuento | B7: 0.11
A8: VPN | B8: =B6+NPV(B7,C6:H6) -> 3832.2712
A9: Decisión | B9: =IF(B8>0,"Viable","No viable") -> Viable
A10: r1 (VPN positivo) | B10: 0.11
A11: VPN a r1 | B11: =B6+NPV(B10,C6:H6) -> 3832.2712
A12: r2 (VPN negativo) | B12: 0.12
A13: VPN a r2 | B13: =B6+NPV(B12,C6:H6) -> -3315.5606
A14: TIR por interpolación | B14: =B10+(B12-B10)*B11/(B11-B13) -> 0.11536145
A15: TIR exacta | B15: =IRR(B6:H6) -> 0.11530473
A18: Ejercicio 5
A19: Concepto | B19: Año 0 | C19: Año 1 | D19: Año 2 | E19: Año 3 | F19: Año 4
A20: Flujo | B20: -50000 | C20: 7500 | D20: 12000 | E20: 20000 | F20: 25000
A21: Tasa de descuento | B21: 0.04
A22: VPN | B22: =B20+NPV(B21,C20:F20) -> 7456.245
A23: Decisión | B23: =IF(B22>0,"Viable","No viable") -> Viable
A24: r1 (VPN positivo) | B24: 0.04
A25: VPN a r1 | B25: =B20+NPV(B24,C20:F20) -> 7456.245
A26: r2 (VPN negativo) | B26: 0.1
A27: VPN a r2 | B27: =B20+NPV(B26,C20:F20) -> -1162.8304
A28: TIR por interpolación | B28: =B24+(B26-B24)*B25/(B25-B27) -> 0.091905185
A29: TIR exacta | B29: =IRR(B20:F20) -> 0.091023577
A32: Ejercicio 6 — Maquinaria (año 4 incluye salvamento de 150K)
A33: Concepto | B33: Año 0 | C33: Año 1 | D33: Año 2 | E33: Año 3 | F33: Año 4
A34: Flujo | B34: -1000000 | C34: 300000 | D34: 350000 | E34: 375000 | F34: 450000
A35: Tasa de descuento | B35: 0.1
A36: VPN | B36: =B34+NPV(B35,C34:F34) -> 151082.58
A37: Decisión | B37: =IF(B36>0,"Viable","No viable") -> Viable
A38: r1 (VPN positivo) | B38: 0.1
A39: VPN a r1 | B39: =B34+NPV(B38,C34:F34) -> 151082.58
A40: r2 (VPN negativo) | B40: 0.2
A41: VPN a r2 | B41: =B34+NPV(B40,C34:F34) -> -72916.667
A42: TIR por interpolación | B42: =B38+(B40-B38)*B39/(B39-B41) -> 0.16744781
A43: TIR exacta | B43: =IRR(B34:F34) -> 0.16351234
A46: Ejercicio 7 — Proyecto X
A47: Concepto | B47: Año 0 | C47: Año 1 | D47: Año 2 | E47: Año 3
...
